Workbook

Sheet Summary
A1: Bloomfield, CT - Truck Parking Development
A2: Fixed & variable capex -> cost per stall -> NOI -> DSCR. All figures are formula-driven from the Assumptions tab.
A4: Metric | B4: Unit | C4: S1 Greenfield Full Asphalt | D4: S2 Greenfield Value-Eng. | E4: S3 Retrofit Existing Yard | F4: Comment
A5: PROGRAM
A6: Gross site area | B6: acres | C6: =Assumptions!$C$6 | D6: =Assumptions!$D$6 | E6: =Assumptions!$E$6
A7: Truck stalls | B7: stalls | C7: =Assumptions!$C$9 | D7: =Assumptions!$D$9 | E7: =Assumptions!$E$9
A8: Density | B8: stalls / acre | C8: =Assumptions!$C$10 | D8: =Assumptions!$D$10 | E8: =Assumptions!$E$10
A9: CAPITAL COST
A10: Fixed capex | B10: $ | C10: =Cost_Per_Stall!$C$42 | D10: =Cost_Per_Stall!$D$42 | E10: =Cost_Per_Stall!$E$42
A11: Variable capex | B11: $ | C11: =Cost_Per_Stall!$C$41 | D11: =Cost_Per_Stall!$D$41 | E11: =Cost_Per_Stall!$E$41
A12: TOTAL PROJECT COST | B12: $ | C12: =Cost_Per_Stall!$C$38 | D12: =Cost_Per_Stall!$D$38 | E12: =Cost_Per_Stall!$E$38
A13: Fixed cost per stall | B13: $ / stall | C13: =Cost_Per_Stall!$C$45 | D13: =Cost_Per_Stall!$D$45 | E13: =Cost_Per_Stall!$E$45
A14: Variable cost per stall | B14: $ / stall | C14: =Cost_Per_Stall!$C$44 | D14: =Cost_Per_Stall!$D$44 | E14: =Cost_Per_Stall!$E$44
A15: ALL-IN COST PER STALL | B15: $ / stall | C15: =Cost_Per_Stall!$C$46 | D15: =Cost_Per_Stall!$D$46 | E15: =Cost_Per_Stall!$E$46 | F15: Fixed costs dominate - see the fixed-share line below. Density is therefore the strongest single lever on this number.
A16: Fixed share of all-in cost | B16: % | C16: =Cost_Per_Stall!$C$48 | D16: =Cost_Per_Stall!$D$48 | E16: =Cost_Per_Stall!$E$48
A17: Land per stall | B17: $ / stall | C17: =Cost_Per_Stall!$C$47 | D17: =Cost_Per_Stall!$D$47 | E17: =Cost_Per_Stall!$E$47
A18: STABILIZED OPERATIONS
A19: Effective gross income | B19: $ / yr | C19: =Revenue_NOI!$C$15 | D19: =Revenue_NOI!$D$15 | E19: =Revenue_NOI!$E$15
A20: Blended revenue per stall | B20: $ / stall / mo | C20: =Revenue_NOI!$C$16 | D20: =Revenue_NOI!$D$16 | E20: =Revenue_NOI!$E$16
A21: Operating expenses | B21: $ / yr | C21: =Revenue_NOI!$C$35 | D21: =Revenue_NOI!$D$35 | E21: =Revenue_NOI!$E$35
A22: Opex ratio | B22: % of EGI | C22: =Revenue_NOI!$C$36 | D22: =Revenue_NOI!$D$36 | E22: =Revenue_NOI!$E$36
A23: Real estate taxes | B23: $ / yr | C23: =Revenue_NOI!$C$20 | D23: =Revenue_NOI!$D$20 | E23: =Revenue_NOI!$E$20
A24: NET OPERATING INCOME | B24: $ / yr | C24: =Revenue_NOI!$C$40 | D24: =Revenue_NOI!$D$40 | E24: =Revenue_NOI!$E$40
A25: NOI per stall | B25: $ / stall / yr | C25: =Revenue_NOI!$C$42 | D25: =Revenue_NOI!$D$42 | E25: =Revenue_NOI!$E$42
A26: YIELD ON COST | B26: % | C26: =Revenue_NOI!$C$43 | D26: =Revenue_NOI!$D$43 | E26: =Revenue_NOI!$E$43
A27: Stabilized value at exit cap | B27: $ | C27: =Revenue_NOI!$C$44 | D27: =Revenue_NOI!$D$44 | E27: =Revenue_NOI!$E$44
A28: Development profit / (loss) | B28: $ | C28: =Revenue_NOI!$C$45 | D28: =Revenue_NOI!$D$45 | E28: =Revenue_NOI!$E$45
A29: FINANCING & COVERAGE
A30: Loan at target 65% LTC | B30: $ | C30: =Debt_DSCR!$C$10 | D30: =Debt_DSCR!$D$10 | E30: =Debt_DSCR!$E$10
A31: Annual debt service | B31: $ / yr | C31: =Debt_DSCR!$C$22 | D31: =Debt_DSCR!$D$22 | E31: =Debt_DSCR!$E$22
A32: DSCR AT TARGET LEVERAGE | B32: x | C32: =Debt_DSCR!$C$23 | D32: =Debt_DSCR!$D$23 | E32: =Debt_DSCR!$E$23 | F32: Test is 1.25x. See Debt_DSCR tab for the sized loan.
A33: Pass / fail vs. 1.25x | C33: =Debt_DSCR!$C$24 | D33: =Debt_DSCR!$D$24 | E33: =Debt_DSCR!$E$24
A34: Debt yield | B34: % | C34: =Debt_DSCR!$C$25 | D34: =Debt_DSCR!$D$25 | E34: =Debt_DSCR!$E$25
A35: Supportable loan (lesser of LTC / LTV / DSCR) | B35: $ | C35: =Debt_DSCR!$C$13 | D35: =Debt_DSCR!$D$13 | E35: =Debt_DSCR!$E$13
A36: Required equity | B36: $ | C36: =Debt_DSCR!$C$16 | D36: =Debt_DSCR!$D$16 | E36: =Debt_DSCR!$E$16
A37: WHAT THE DEAL NEEDS (break-evens at 1.25x DSCR, 65% LTC)
A38: Required blended revenue per stall | B38: $ / stall / mo | C38: =Debt_DSCR!$C$33 | D38: =Debt_DSCR!$D$33 | E38: =Debt_DSCR!$E$33
A39: Modeled blended revenue per stall | B39: $ / stall / mo | C39: =Revenue_NOI!$C$16 | D39: =Revenue_NOI!$D$16 | E39: =Revenue_NOI!$E$16
A40: Rate gap | B40: % | C40: =Debt_DSCR!$C$35 | D40: =Debt_DSCR!$D$35 | E40: =Debt_DSCR!$E$35
A41: Maximum supportable cost per stall | B41: $ / stall | C41: =Debt_DSCR!$C$37 | D41: =Debt_DSCR!$D$37 | E41: =Debt_DSCR!$E$37
...

Sheet Assumptions
A1: Bloomfield, CT | Truck Parking Development - Assumptions
A2: Blue = hardcoded input / scenario lever. Black = formula. Yellow fill = key assumption to pressure-test.
A4: Assumption | B4: Unit / Basis | C4: S1 Greenfield Full Asphalt | D4: S2 Greenfield Value-Eng. | E4: S3 Retrofit Existing Yard | F4: Basis / Source
A5: 1. SITE & PROGRAM
A6: Gross site area | B6: acres | C6: 10 | D6: 10 | E6: 8 | F6: Target: I-1 / PID industrial parcel, Bloomfield (Blue Hills Ave / Tobey Rd / Douglas St corridor), ~10 min to I-91 via Rts 218/291.
A7: Net yard efficiency (paveable / gross) | B7: % of gross | C7: 0.72 | D7: 0.72 | E7: 0.78 | F7: Deductions: front/side setbacks, landscape buffer, stormwater basin, wetland buffer, entry drive, auto parking. S3 higher - already improved.
A8: Paved area per stall (incl. drive aisle) | B8: SF / stall | C8: 1450 | D8: 1450 | E8: 1450 | F8: 12' x 75' stall = 900 SF + half of a 75' back-in aisle (450 SF) + 100 SF cross-lanes/tapers.
A9: Truck stalls (53' tractor-trailer) | B9: stalls | C9: =ROUNDDOWN($C$6*43560*$C$7/$C$8,0) | D9: =ROUNDDOWN($D$6*43560*$D$7/$D$8,0) | E9: =ROUNDDOWN($E$6*43560*$E$7/$E$8,0) | F9: Implied density shown below; industry rule of thumb is 20-25 stalls per gross acre.
A10: Implied density | B10: stalls / gross acre | C10: =$C$9/$C$6 | D10: =$D$9/$D$6 | E10: =$E$9/$E$6
A11: Paved yard area | B11: SF | C11: =$C$9*$C$8 | D11: =$D$9*$D$8 | E11: =$E$9*$E$8
A12: Paved yard area | B12: acres | C12: =$C$11/43560 | D12: =$D$11/43560 | E12: =$E$11/43560
A13: Perimeter fence length | B13: LF | C13: =ROUND(4*SQRT($C$6*43560),0) | D13: =ROUND(4*SQRT($D$6*43560),0) | E13: =ROUND(4*SQRT($E$6*43560),0) | F13: Square-site approximation: 4 x SQRT(site SF). Irregular parcels run 10-25% longer.
A14: 2. LAND / SITE ACQUISITION
A15: Land price | B15: $ / acre | C15: 175000 | D15: 175000 | E15: 385000 | F15: Hartford-metro industrial land. Raw unentitled Bloomfield acreage $100-200k/ac; already-paved improved yard (S3) $325-450k/ac. CT industrial land avg ~$110k/ac (LandSearch).
A16: Land / acquisition cost | B16: $ | C16: =$C$15*$C$6 | D16: =$D$15*$D$6 | E16: =$E$15*$E$6
A17: Acquisition closing costs | B17: % of price | C17: 0.022 | D17: 0.022 | E17: 0.022 | F17: CT conveyance tax, title, survey update, buyer legal, broker cost share.
A18: 3. REVENUE
A19: Stalls sold as monthly reserved | B19: % of stalls | C19: 0.8 | D19: 0.8 | E19: 0.85 | F19: Bloomfield is an off-highway 'home-base / drop-lot' market, not a highway truck stop. Monthly contracts dominate; balance sold transient.
A20: Monthly reserved rate | B20: $ / stall / month | C20: 340 | D20: 315 | E20: 325 | F20: Secured, lit, gated 53' stall. Northeast private lots run $150-500/mo; Hartford metro is the low end of that band. S1 premium for full pave + staffing.
A21: Stabilized occupancy - monthly stalls | B21: % | C21: 0.9 | D21: 0.88 | E21: 0.9 | F21: Tech-enabled operators report 92-98% at stabilization; 88-90% underwritten.
A22: Transient rate | B22: $ / stall / night | C22: 26 | D22: 24 | E22: 25 | F22: Chain travel centers charge $12-25/night for reserved parking; secured off-highway lots price at the top of that band.
A23: Stabilized utilization - transient stalls | B23: % of nights | C23: 0.62 | D23: 0.58 | E23: 0.6
A24: Ancillary revenue | B24: % of parking EGI | C24: 0.05 | D24: 0.03 | E24: 0.035 | F24: Reefer/APU plug-in fees, unpowered trailer storage, vendor space rent (mobile repair/tire), vending, wash bay referral. S1 has driver services building.
A25: Credit loss / bad debt | B25: % of gross rent | C25: 0.02 | D25: 0.02 | E25: 0.02 | F25: Owner-operator credit is thin; prepay + card-on-file mitigates.
A26: Revenue growth | B26: % p.a. | C26: 0.03 | D26: 0.03 | E26: 0.03
A27: 4. OPERATING EXPENSES (Year-1 stabilized dollars)
A28: Bloomfield mill rate | B28: mills | C28: 34.4 | D28: 34.4 | E28: 34.4 | F28: 2025 Grand List adopted mill rate for real & personal property (Town of Bloomfield); year 2 of a 4-year revaluation phase-in. FY26 budget forum projected ~34.03.
A29: CT assessment ratio | B29: % of market value | C29: 0.7 | D29: 0.7 | E29: 0.7 | F29: Statutory: CT assesses at 70% of fair market value.
A30: Assessor value - land | B30: % of land cost | C30: 1 | D30: 1 | E30: 1
A31: Assessor value - improvements | B31: % of improvement cost | C31: 0.45 | D31: 0.45 | E31: 0.45 | F31: LARGEST SINGLE MODELING UNCERTAINTY. Site improvements (paving, fence, lighting) are typically assessed well below cost, but a CT assessor can also value on the income approach. Sensitized on the Sensitivity tab.
A32: Insurance - GL, property, garagekeepers | B32: $ / stall / yr | C32: 230 | D32: 210 | E32: 220 | F32: Garagekeepers legal liability is the coverage IOS truck-parking operators must carry beyond standard GL.
A33: On-site staffing / attendant | B33: $ / yr | C33: 165000 | D33: 0 | E33: 0 | F33: S1 assumes 16 hr/day attended gate. S2/S3 are unmanned, tech-gated.
A34: Remote monitoring + roving patrol | B34: $ / yr | C34: 42000 | D34: 52000 | E34: 50000 | F34: Unmanned sites carry a heavier monitoring/patrol contract.
A35: Snow & ice management | B35: $ / paved acre / yr | C35: 8800 | D35: 8200 | E35: 8800 | F35: CT: ~18-22 plow events/season plus salting on a large yard. Real cost driver in this climate; gravel stalls (S2) plow slightly cheaper but rut.
A36: Repairs, maintenance, sweeping, striping | B36: $ / stall / yr | C36: 210 | D36: 235 | E36: 225 | F36: S2 higher: millings surface needs annual regrading and dust control.
A37: Utilities - lighting, water, sewer, telecom | B37: $ / stall / yr | C37: 165 | D37: 145 | E37: 150
A38: Trash, restrooms, janitorial | B38: $ / stall / yr | C38: 95 | D38: 70 | E38: 75
A39: Property management fee | B39: % of EGI | C39: 0.04 | D39: 0.04 | E39: 0.04
A40: Payment processing + reservation platform | B40: % of parking revenue | C40: 0.02 | D40: 0.015 | E40: 0.015 | F40: Monthly ACH ~1%; card/transient 2.9% + platform fee. Blended by revenue mix.
A41: Marketing & leasing | B41: $ / stall / yr | C41: 75 | D41: 85 | E41: 80
...

Sheet Capex_Variable
A1: Variable Capex - costs that scale directly with stall count
A2: Unit costs are blue inputs. Everything here grows one-for-one with the size of the paved yard, so it sets the MARGINAL cost of a stall.
A4: Cost item | B4: Unit | C4: S1 Greenfield Full Asphalt | D4: S2 Greenfield Value-Eng. | E4: S3 Retrofit Existing Yard | F4: Basis / Source
A5: A. YARD CONSTRUCTION ($ per SF of paved yard)
A6: Clearing, grubbing, erosion & sediment control | B6: $ / SF | C6: 0.35 | D6: 0.35 | E6: 0.05
A7: Mass grading & earthwork (balanced site) | B7: $ / SF | C7: 1.75 | D7: 1.55 | E7: 0.2 | F7: Assumes a cut/fill-balanced site with no rock or unsuitable-soil export. Ledge or peat is the single biggest greenfield cost shock in this part of CT.
A8: Subgrade prep, geotextile, 12" processed aggregate base | B8: $ / SF | C8: 2.4 | D8: 2.05 | E8: 0.15 | F8: Heavy-duty truck section: 10-12"+ of aggregate base under the wearing course.
A9: Surface course | B9: $ / SF | C9: 4.35 | D9: 1.95 | E9: 1.85 | F9: S1: 5" bituminous (3" binder + 2" wearing). S2: paved aisles (~32% of area) blended with compacted millings/crushed stone stalls. S3: mill & 2" overlay + full-depth patching. CT commercial asphalt $4-11/SF; heavy-duty truck sections $7-12/SF; CT construction costs run ~1.32x national.
A10: Storm conveyance within yard (catch basins, piping) | B10: $ / SF | C10: 0.48 | D10: 0.44 | E10: 0.12
A11: Striping, wheel stops, bollards | B11: $ / SF | C11: 0.12 | D11: 0.1 | E11: 0.12
A12: Subtotal - yard construction | B12: $ / SF | C12: =SUM(C6:C11) | D12: =SUM(D6:D11) | E12: =SUM(E6:E11)
A13: Yard construction - total | B13: $ | C13: =C12*Assumptions!$C$11 | D13: =D12*Assumptions!$D$11 | E13: =E12*Assumptions!$E$11
A15: B. PER-STALL DISCRETE ITEMS ($ per stall)
A16: Yard lighting - LED on 30' poles | B16: $ / stall | C16: 1225 | D16: 1225 | E16: 1225 | F16: 1 pole per 8 stalls at ~$9,800 installed (pole, fixture, base, conduit, wire).
A17: Yard electrical distribution, conduit, panels | B17: $ / stall | C17: 375 | D17: 340 | E17: 300
A18: Reefer / APU power pedestals (30A) | B18: $ / stall | C18: 620 | D18: 0 | E18: 310 | F18: $3,100 per pedestal on 20% of stalls (S1) / 10% (S3). Reefer plug-ins are the highest-margin ancillary line but add electrical service load.
A19: Camera coverage & analytics - incremental | B19: $ / stall | C19: 185 | D19: 210 | E19: 210 | F19: Head-end / NVR is a fixed cost; this is the marginal camera density per added row of stalls.
A20: Subtotal - per-stall items | B20: $ / stall | C20: =SUM(C16:C19) | D20: =SUM(D16:D19) | E20: =SUM(E16:E19)
A21: Per-stall items - total | B21: $ | C21: =C20*Assumptions!$C$9 | D21: =D20*Assumptions!$D$9 | E21: =E20*Assumptions!$E$9
A23: TOTAL VARIABLE HARD COST | B23: $ | C23: =C13+C21 | D23: =D13+D21 | E23: =E13+E21
A24: Variable hard cost per stall | B24: $ / stall | C24: =C23/Assumptions!$C$9 | D24: =D23/Assumptions!$D$9 | E24: =E23/Assumptions!$E$9
A26: Note: soft-cost loadings and contingency are allocated pro-rata between fixed and variable on the Cost_Per_Stall tab; this page is hard cost only.

Sheet Capex_Fixed
A1: Fixed Capex - site-level threshold costs
A2: These are incurred to open the gate at all. They do NOT scale with stall count, which is why density and site size drive this deal.
A4: Cost item | B4: Unit | C4: S1 Greenfield Full Asphalt | D4: S2 Greenfield Value-Eng. | E4: S3 Retrofit Existing Yard | F4: Basis / Source
A5: A. LAND / ACQUISITION
A6: Land / site purchase price | B6: $ | C6: =Assumptions!$C$16 | D6: =Assumptions!$D$16 | E6: =Assumptions!$E$16
A7: Acquisition closing costs | B7: $ | C7: =C6*Assumptions!$C$17 | D7: =D6*Assumptions!$D$17 | E7: =E6*Assumptions!$E$17
A8: Subtotal - acquisition | B8: $ | C8: =SUM(C6:C7) | D8: =SUM(D6:D7) | E8: =SUM(E6:E7)
A10: B. PRE-DEVELOPMENT, DESIGN & ENTITLEMENT
A11: ALTA / topographic survey | B11: $ | C11: 14000 | D11: 14000 | E11: 12000
A12: Geotechnical investigation (borings, pavement design) | B12: $ | C12: 22000 | D12: 22000 | E12: 14000
A13: Phase I ESA | B13: $ | C13: 4000 | D13: 4000 | E13: 4500
A14: Phase II ESA / LEP remediation allowance | B14: $ | C14: 35000 | D14: 35000 | E14: 95000 | F14: CT's Transfer Act has been replaced by the Release-Based Remediation program. A previously-industrial paved yard (S3) carries real recognized-environmental-condition risk - this is an allowance, not a budget.
A15: Wetlands delineation & IWWA permitting | B15: $ | C15: 18000 | D15: 18000 | E15: 6000 | F15: Bloomfield Inland Wetlands & Watercourses Agency. Much of the town's remaining industrial acreage carries wetland or watercourse constraints.
A16: Traffic impact study | B16: $ | C16: 28000 | D16: 28000 | E16: 22000 | F16: A 150-250 stall facility generates enough heavy-vehicle trips to trigger a full TIS and likely CT OSTA review.
A17: Civil engineering & site design | B17: $ | C17: 195000 | D17: 175000 | E17: 85000
A18: Architectural - gatehouse / driver services | B18: $ | C18: 18000 | D18: 12000 | E18: 12000
A19: Land-use counsel & entitlement | B19: $ | C19: 85000 | D19: 85000 | E19: 55000 | F19: ENTITLEMENT IS THE GATING RISK. Bloomfield TPZ has treated outdoor storage as a non-permitted principal use - approved only as an accessory use by special permit, with a ZBA variance otherwise required. A standalone commercial truck-parking yard likely needs a zoning text amendment or variance, not just site-plan approval.
A20: Municipal application & review fees | B20: $ | C20: 18000 | D20: 18000 | E20: 12000
A21: CT DEEP stormwater GP registration + SWPPP | B21: $ | C21: 22000 | D21: 22000 | E21: 10000
A22: Driveway / encroachment permits | B22: $ | C22: 12000 | D22: 12000 | E22: 4000
A23: Subtotal - pre-development | B23: $ | C23: =SUM(C11:C22) | D23: =SUM(D11:D22) | E23: =SUM(E11:E22)
A25: C. SITE INFRASTRUCTURE (hard cost, non-stall)
A26: Demolition & clearing outside the yard | B26: $ | C26: 95000 | D26: 95000 | E26: 165000 | F26: S3 assumes demolition of an obsolete building on the existing yard.
A27: Stormwater basin, water-quality units, outlet control | B27: $ | C27: 385000 | D27: 355000 | E27: 120000 | F27: Truck yards are a regulated industrial stormwater activity in CT - treatment train plus spill controls, not just detention.
A28: Site entry, apron, turn lane, sight-line work | B28: $ | C28: 195000 | D28: 175000 | E28: 110000
A29: Perimeter fence - 8' chain link, slats, barbed arm | B29: $ | C29: =Assumptions!$C$13*58 | D29: =Assumptions!$D$13*52 | E29: =Assumptions!$E$13*52 | F29: $52-58 per LF installed on the perimeter LF calculated on the Assumptions tab.
A30: Automated gates, operators, LPR / RFID access control | B30: $ | C30: 155000 | D30: 145000 | E30: 145000
A31: Security head-end - NVR, analytics, network, lighting controls | B31: $ | C31: 145000 | D31: 175000 | E31: 165000 | F31: Unmanned sites (S2/S3) invest more in technology to substitute for staff.
A32: Gatehouse / driver services building + restrooms | B32: $ | C32: 265000 | D32: 145000 | E32: 155000
A33: Utility service - electric & transformer, water, sewer/septic, fiber | B33: $ | C33: 210000 | D33: 185000 | E33: 95000
A34: Landscaping, buffer plantings, signage, ADA auto parking | B34: $ | C34: 135000 | D34: 105000 | E34: 65000
A35: TOTAL FIXED HARD COST | B35: $ | C35: =SUM(C26:C34) | D35: =SUM(D26:D34) | E35: =SUM(E26:E34)

Sheet Cost_Per_Stall
A1: All-In Development Cost -> Cost Per Stall
A2: Soft-cost loadings and contingency are allocated pro-rata between fixed and variable by share of hard cost.
B4: Unit | C4: S1 Greenfield Full Asphalt | D4: S2 Greenfield Value-Eng. | E4: S3 Retrofit Existing Yard | F4: Note
A5: A. HARD COSTS
A6: Fixed hard cost - site infrastructure | B6: $ | C6: =Capex_Fixed!$C$35 | D6: =Capex_Fixed!$D$35 | E6: =Capex_Fixed!$E$35
A7: Variable hard cost - yard & stalls | B7: $ | C7: =Capex_Variable!$C$23 | D7: =Capex_Variable!$D$23 | E7: =Capex_Variable!$E$23
A8: Total hard cost | B8: $ | C8: =C6+C7 | D8: =D6+D7 | E8: =E6+E7
A9: Variable share of hard cost | B9: % | C9: =C7/C8 | D9: =D7/D8 | E9: =E7/E8
A11: B. SOFT-COST LOADINGS & CONTINGENCY
A12: Construction management / owner's rep | B12: $ | C12: =C8*Assumptions!$C$46 | D12: =D8*Assumptions!$D$46 | E12: =E8*Assumptions!$E$46
A13: Testing, inspection, materials QA | B13: $ | C13: =C8*Assumptions!$C$47 | D13: =D8*Assumptions!$D$47 | E13: =E8*Assumptions!$E$47
A14: Builder's risk & GL during construction | B14: $ | C14: =C8*Assumptions!$C$48 | D14: =D8*Assumptions!$D$48 | E14: =E8*Assumptions!$E$48
A15: Performance / payment bonds | B15: $ | C15: =C8*Assumptions!$C$49 | D15: =D8*Assumptions!$D$49 | E15: =E8*Assumptions!$E$49
A16: Subtotal - soft-cost loadings | B16: $ | C16: =SUM(C12:C15) | D16: =SUM(D12:D15) | E16: =SUM(E12:E15)
A17: Contingency | B17: $ | C17: =(C8+C16)*Assumptions!$C$50 | D17: =(D8+D16)*Assumptions!$D$50 | E17: =(E8+E16)*Assumptions!$E$50
A18: TOTAL CONSTRUCTION COST | B18: $ | C18: =C8+C16+C17 | D18: =D8+D16+D17 | E18: =E8+E16+E17
A20: C. LAND, PRE-DEVELOPMENT & FINANCING (100% fixed)
A21: Land & acquisition costs | B21: $ | C21: =Capex_Fixed!$C$8 | D21: =Capex_Fixed!$D$8 | E21: =Capex_Fixed!$E$8
A22: Pre-development, design & entitlement | B22: $ | C22: =Capex_Fixed!$C$23 | D22: =Capex_Fixed!$D$23 | E22: =Capex_Fixed!$E$23
A23: Improvement cost basis (for tax assessment) | B23: $ | C23: =C18+C22 | D23: =D18+D22 | E23: =E18+E22 | F23: Assessor's improvement basis = construction + pre-development. Land assessed separately.
A24: Project cost before financing | B24: $ | C24: =C18+C21+C22 | D24: =D18+D21+D22 | E24: =E18+E21+E22
A25: Construction loan amount | B25: $ | C25: =C24*Assumptions!$C$52 | D25: =D24*Assumptions!$D$52 | E25: =E24*Assumptions!$E$52
A26: Construction loan origination fee | B26: $ | C26: =C25*Assumptions!$C$56 | D26: =D25*Assumptions!$D$56 | E26: =E25*Assumptions!$E$56
A27: Construction period interest | B27: $ | C27: =C25*Assumptions!$C$53*Assumptions!$C$55*Assumptions!$C$54/12 | D27: =D25*Assumptions!$D$53*Assumptions!$D$55*Assumptions!$D$54/12 | E27: =E25*Assumptions!$E$53*Assumptions!$E$55*Assumptions!$E$54/12
A28: Lender costs - appraisal, environmental, legal, title | B28: $ | C28: =Assumptions!$C$57 | D28: =Assumptions!$D$57 | E28: =Assumptions!$E$57
A29: Real estate taxes during construction | B29: $ | C29: =Capex_Fixed!$C$6*Assumptions!$C$29*Assumptions!$C$28/1000*Assumptions!$C$54/12 | D29: =Capex_Fixed!$D$6*Assumptions!$D$29*Assumptions!$D$28/1000*Assumptions!$D$54/12 | E29: =Capex_Fixed!$E$6*Assumptions!$E$29*Assumptions!$E$28/1000*Assumptions!$E$54/12
A30: Subtotal - financing & carry | B30: $ | C30: =SUM(C26:C29) | D30: =SUM(D26:D29) | E30: =SUM(E26:E29)
A31: Capitalized cost before lease-up reserve | B31: $ | C31: =C24+C30 | D31: =D24+D30 | E31: =E24+E30
A33: D. LEASE-UP RESERVE
A34: Operating reserve during lease-up | B34: $ | C34: =Revenue_NOI!$C$35*Assumptions!$C$64/12 | D34: =Revenue_NOI!$D$35*Assumptions!$D$64/12 | E34: =Revenue_NOI!$E$35*Assumptions!$E$64/12 | F34: Months of stabilized opex carried until the yard fills. Truck-parking assets typically need up to 36 months to reach stabilized occupancy.
A35: Launch marketing / pre-leasing | B35: $ | C35: =Assumptions!$C$65 | D35: =Assumptions!$D$65 | E35: =Assumptions!$E$65
A36: Subtotal - lease-up reserve | B36: $ | C36: =SUM(C34:C35) | D36: =SUM(D34:D35) | E36: =SUM(E34:E35)
A38: TOTAL PROJECT COST | B38: $ | C38: =C31+C36 | D38: =D31+D36 | E38: =E31+E36
A40: E. FIXED vs. VARIABLE -> COST PER STALL
A41: VARIABLE capex (hard + allocated soft & contingency) | B41: $ | C41: =C7+(C16+C17)*C9 | D41: =D7+(D16+D17)*D9 | E41: =E7+(E16+E17)*E9
A42: FIXED capex (everything else) | B42: $ | C42: =C38-C41 | D42: =D38-D41 | E42: =E38-E41
A43: Stalls | B43: stalls | C43: =Assumptions!$C$9 | D43: =Assumptions!$D$9 | E43: =Assumptions!$E$9
A44: Variable cost per stall | B44: $ / stall | C44: =C41/C43 | D44: =D41/D43 | E44: =E41/E43 | F44: The MARGINAL cost of adding one more stall to an already-entitled site. This is the number that should drive the site-layout decision.
A45: Fixed cost per stall | B45: $ / stall | C45: =C42/C43 | D45: =D42/D43 | E45: =E42/E43 | F45: Site-level costs spread over the stall count. Falls as density rises - the single biggest lever on cost per stall.
A46: ALL-IN COST PER STALL | B46: $ / stall | C46: =C38/C43 | D46: =D38/D43 | E46: =E38/E43
...

Sheet Revenue_NOI
A1: Stabilized Revenue, Operating Expenses & NOI
A2: Year-1-stabilized dollars. Reserves are deducted before NOI because lenders size debt to a reserve-burdened NOI.
B4: Unit | C4: S1 Greenfield Full Asphalt | D4: S2 Greenfield Value-Eng. | E4: S3 Retrofit Existing Yard | F4: Note
A5: A. REVENUE
A6: Stalls - monthly reserved | B6: stalls | C6: =ROUND(Assumptions!$C$9*Assumptions!$C$19,0) | D6: =ROUND(Assumptions!$D$9*Assumptions!$D$19,0) | E6: =ROUND(Assumptions!$E$9*Assumptions!$E$19,0)
A7: Stalls - transient / nightly | B7: stalls | C7: =Assumptions!$C$9-C6 | D7: =Assumptions!$D$9-D6 | E7: =Assumptions!$E$9-E6
A8: Gross potential rent - monthly stalls | B8: $ / yr | C8: =C6*Assumptions!$C$20*12 | D8: =D6*Assumptions!$D$20*12 | E8: =E6*Assumptions!$E$20*12
A9: Gross potential rent - transient stalls | B9: $ / yr | C9: =C7*Assumptions!$C$22*365 | D9: =D7*Assumptions!$D$22*365 | E9: =E7*Assumptions!$E$22*365
A10: Gross potential rent | B10: $ / yr | C10: =C8+C9 | D10: =D8+D9 | E10: =E8+E9
A11: Less: vacancy / unutilized nights | B11: $ / yr | C11: =-(C8*(1-Assumptions!$C$21)+C9*(1-Assumptions!$C$23)) | D11: =-(D8*(1-Assumptions!$D$21)+D9*(1-Assumptions!$D$23)) | E11: =-(E8*(1-Assumptions!$E$21)+E9*(1-Assumptions!$E$23))
A12: Less: credit loss / bad debt | B12: $ / yr | C12: =-(C10+C11)*Assumptions!$C$25 | D12: =-(D10+D11)*Assumptions!$D$25 | E12: =-(E10+E11)*Assumptions!$E$25
A13: Net parking revenue | B13: $ / yr | C13: =SUM(C10:C12) | D13: =SUM(D10:D12) | E13: =SUM(E10:E12)
A14: Ancillary revenue | B14: $ / yr | C14: =C13*Assumptions!$C$24 | D14: =D13*Assumptions!$D$24 | E14: =E13*Assumptions!$E$24
A15: EFFECTIVE GROSS INCOME | B15: $ / yr | C15: =C13+C14 | D15: =D13+D14 | E15: =E13+E14
A16: Blended revenue per stall per month | B16: $ / stall / mo | C16: =C15/Assumptions!$C$9/12 | D16: =D15/Assumptions!$D$9/12 | E16: =E15/Assumptions!$E$9/12
A17: Revenue per gross acre | B17: $ / acre / yr | C17: =C15/Assumptions!$C$6 | D17: =D15/Assumptions!$D$6 | E17: =E15/Assumptions!$E$6 | F17: Cross-check: bulk NNN truck-yard leases in Hartford metro trade around $35,000-55,000 per acre per year. A per-stall retail operation must beat that to justify the operating overhead.
A19: B. OPERATING EXPENSES
A20: Real estate taxes | B20: $ / yr | C20: =(Capex_Fixed!$C$6*Assumptions!$C$30+Cost_Per_Stall!$C$23*Assumptions!$C$31)*Assumptions!$C$29*Assumptions!$C$28/1000 | D20: =(Capex_Fixed!$D$6*Assumptions!$D$30+Cost_Per_Stall!$D$23*Assumptions!$D$31)*Assumptions!$D$29*Assumptions!$D$28/1000 | E20: =(Capex_Fixed!$E$6*Assumptions!$E$30+Cost_Per_Stall!$E$23*Assumptions!$E$31)*Assumptions!$E$29*Assumptions!$E$28/1000 | F20: (Land x land factor + improvements x improvement factor) x 70% assessment ratio x mill rate / 1000.
A21: Insurance | B21: $ / yr | C21: =Assumptions!$C$32*Assumptions!$C$9 | D21: =Assumptions!$D$32*Assumptions!$D$9 | E21: =Assumptions!$E$32*Assumptions!$E$9
A22: On-site staffing | B22: $ / yr | C22: =Assumptions!$C$33 | D22: =Assumptions!$D$33 | E22: =Assumptions!$E$33
A23: Remote monitoring & patrol | B23: $ / yr | C23: =Assumptions!$C$34 | D23: =Assumptions!$D$34 | E23: =Assumptions!$E$34
A24: Snow & ice management | B24: $ / yr | C24: =Assumptions!$C$35*Assumptions!$C$12 | D24: =Assumptions!$D$35*Assumptions!$D$12 | E24: =Assumptions!$E$35*Assumptions!$E$12
A25: Repairs & maintenance | B25: $ / yr | C25: =Assumptions!$C$36*Assumptions!$C$9 | D25: =Assumptions!$D$36*Assumptions!$D$9 | E25: =Assumptions!$E$36*Assumptions!$E$9
A26: Utilities | B26: $ / yr | C26: =Assumptions!$C$37*Assumptions!$C$9 | D26: =Assumptions!$D$37*Assumptions!$D$9 | E26: =Assumptions!$E$37*Assumptions!$E$9
A27: Trash, restrooms, janitorial | B27: $ / yr | C27: =Assumptions!$C$38*Assumptions!$C$9 | D27: =Assumptions!$D$38*Assumptions!$D$9 | E27: =Assumptions!$E$38*Assumptions!$E$9
A28: Marketing & leasing | B28: $ / yr | C28: =Assumptions!$C$41*Assumptions!$C$9 | D28: =Assumptions!$D$41*Assumptions!$D$9 | E28: =Assumptions!$E$41*Assumptions!$E$9
A29: Professional fees, legal, accounting, admin | B29: $ / yr | C29: =Assumptions!$C$42 | D29: =Assumptions!$D$42 | E29: =Assumptions!$E$42
A30: Replacement reserve | B30: $ / yr | C30: =Assumptions!$C$43*Assumptions!$C$9 | D30: =Assumptions!$D$43*Assumptions!$D$9 | E30: =Assumptions!$E$43*Assumptions!$E$9
A31: Subtotal - revenue-independent opex | B31: $ / yr | C31: =SUM(C20:C30) | D31: =SUM(D20:D30) | E31: =SUM(E20:E30) | F31: Does not move with occupancy - drives the operating leverage in this asset class.
A32: Property management fee | B32: $ / yr | C32: =C15*Assumptions!$C$39 | D32: =D15*Assumptions!$D$39 | E32: =E15*Assumptions!$E$39
A33: Payment processing & reservation platform | B33: $ / yr | C33: =C13*Assumptions!$C$40 | D33: =D13*Assumptions!$D$40 | E33: =E13*Assumptions!$E$40
A34: Subtotal - revenue-linked opex | B34: $ / yr | C34: =C32+C33 | D34: =D32+D33 | E34: =E32+E33
A35: TOTAL OPERATING EXPENSES | B35: $ / yr | C35: =C31+C34 | D35: =D31+D34 | E35: =E31+E34
A36: Opex ratio | B36: % of EGI | C36: =C35/C15 | D36: =D35/D15 | E36: =E35/E15
A37: Opex per stall per month | B37: $ / stall / mo | C37: =C35/Assumptions!$C$9/12 | D37: =D35/Assumptions!$D$9/12 | E37: =E35/Assumptions!$E$9/12
A38: Revenue-linked opex as % of EGI | B38: % | C38: =C34/C15 | D38: =D34/D15 | E38: =E34/E15
A40: NET OPERATING INCOME (after reserves) | B40: $ / yr | C40: =C15-C35 | D40: =D15-D35 | E40: =E15-E35
A41: NOI before replacement reserves | B41: $ / yr | C41: =C40+C30 | D41: =D40+D30 | E41: =E40+E30
A42: NOI per stall | B42: $ / stall / yr | C42: =C40/Assumptions!$C$9 | D42: =D40/Assumptions!$D$9 | E42: =E40/Assumptions!$E$9
A43: YIELD ON COST (NOI / total project cost) | B43: % | C43: =C40/Cost_Per_Stall!$C$38 | D43: =D40/Cost_Per_Stall!$D$38 | E43: =E40/Cost_Per_Stall!$E$38
...

Sheet Debt_DSCR
A1: Debt Sizing, DSCR & Break-Evens
A2: Permanent debt sized to the LESSER of loan-to-cost, loan-to-value and the minimum-DSCR constraint.
B4: Unit | C4: S1 Greenfield Full Asphalt | D4: S2 Greenfield Value-Eng. | E4: S3 Retrofit Existing Yard | F4: Note
A5: A. LOAN SIZING
A6: Total project cost | B6: $ | C6: =Cost_Per_Stall!$C$38 | D6: =Cost_Per_Stall!$D$38 | E6: =Cost_Per_Stall!$E$38
A7: Stabilized NOI | B7: $ / yr | C7: =Revenue_NOI!$C$40 | D7: =Revenue_NOI!$D$40 | E7: =Revenue_NOI!$E$40
A8: Stabilized value | B8: $ | C8: =Revenue_NOI!$C$44 | D8: =Revenue_NOI!$D$44 | E8: =Revenue_NOI!$E$44
A9: Annual debt constant | B9: % | C9: =-PMT(Assumptions!$C$60/12,Assumptions!$C$61*12,1)*12 | D9: =-PMT(Assumptions!$D$60/12,Assumptions!$D$61*12,1)*12 | E9: =-PMT(Assumptions!$E$60/12,Assumptions!$E$61*12,1)*12 | F9: Mortgage constant = annualized payment on $1 of principal.
A10: Loan by max loan-to-cost | B10: $ | C10: =C6*Assumptions!$C$58 | D10: =D6*Assumptions!$D$58 | E10: =E6*Assumptions!$E$58
A11: Loan by max loan-to-value | B11: $ | C11: =C8*Assumptions!$C$59 | D11: =D8*Assumptions!$D$59 | E11: =E8*Assumptions!$E$59
A12: Loan by minimum DSCR | B12: $ | C12: =C7/(Assumptions!$C$62*C9) | D12: =D7/(Assumptions!$D$62*D9) | E12: =E7/(Assumptions!$E$62*E9)
A13: SUPPORTABLE LOAN | B13: $ | C13: =MAX(0,MIN(C10,C11,C12)) | D13: =MAX(0,MIN(D10,D11,D12)) | E13: =MAX(0,MIN(E10,E11,E12))
A14: Binding constraint | C14: =IF(C13=C12,"DSCR",IF(C13=C11,"LTV","LTC")) | D14: =IF(D13=D12,"DSCR",IF(D13=D11,"LTV","LTC")) | E14: =IF(E13=E12,"DSCR",IF(E13=E11,"LTV","LTC"))
A15: Actual loan to cost | B15: % | C15: =C13/C6 | D15: =D13/D6 | E15: =E13/E6
A16: Required equity | B16: $ | C16: =C6-C13 | D16: =D6-D13 | E16: =E6-E13
A17: Equity per stall | B17: $ / stall | C17: =C16/Assumptions!$C$9 | D17: =D16/Assumptions!$D$9 | E17: =E16/Assumptions!$E$9
A19: B. DEBT SERVICE COVERAGE
A20: Annual debt service - at supportable loan | B20: $ / yr | C20: =C13*C9 | D20: =D13*D9 | E20: =E13*E9
A21: DSCR - at supportable loan | B21: x | C21: =IF(C20=0,0,C7/C20) | D21: =IF(D20=0,0,D7/D20) | E21: =IF(E20=0,0,E7/E20)
A22: Annual debt service - if funded at max LTC | B22: $ / yr | C22: =C10*C9 | D22: =D10*D9 | E22: =E10*E9
A23: DSCR - if funded at max LTC | B23: x | C23: =C7/C22 | D23: =D7/D22 | E23: =E7/E22 | F23: THE HEADLINE TEST. This is the coverage a lender would actually see on a request for the target leverage.
A24: Passes minimum DSCR at target leverage? | C24: =IF(C23>=Assumptions!$C$62,"PASS","FAIL") | D24: =IF(D23>=Assumptions!$D$62,"PASS","FAIL") | E24: =IF(E23>=Assumptions!$E$62,"PASS","FAIL")
A25: Debt yield - at max LTC loan | B25: % | C25: =C7/C10 | D25: =D7/D10 | E25: =E7/E10 | F25: Lenders on non-core collateral generally want a 10%+ debt yield.
A26: Cash flow after debt service (supportable loan) | B26: $ / yr | C26: =C7-C20 | D26: =D7-D20 | E26: =E7-E20
A27: Cash-on-cash return on equity | B27: % | C27: =IF(C16<=0,0,C26/C16) | D27: =IF(D16<=0,0,D26/D16) | E27: =IF(E16<=0,0,E26/E16)
A29: C. BREAK-EVENS (what the deal needs in order to clear a 1.25x DSCR at target leverage)
A30: NOI required for minimum DSCR at max LTC | B30: $ / yr | C30: =C22*Assumptions!$C$62 | D30: =D22*Assumptions!$D$62 | E30: =E22*Assumptions!$E$62
A31: NOI surplus / (shortfall) | B31: $ / yr | C31: =C7-C30 | D31: =D7-D30 | E31: =E7-E30
A32: EGI required | B32: $ / yr | C32: =(C30+Revenue_NOI!$C$31)/(1-Revenue_NOI!$C$38) | D32: =(D30+Revenue_NOI!$D$31)/(1-Revenue_NOI!$D$38) | E32: =(E30+Revenue_NOI!$E$31)/(1-Revenue_NOI!$E$38)
A33: Required blended revenue per stall per month | B33: $ / stall / mo | C33: =C32/Assumptions!$C$9/12 | D33: =D32/Assumptions!$D$9/12 | E33: =E32/Assumptions!$E$9/12
A34: vs. modeled blended revenue per stall per month | B34: $ / stall / mo | C34: =Revenue_NOI!$C$16 | D34: =Revenue_NOI!$D$16 | E34: =Revenue_NOI!$E$16
A35: Rate gap | B35: % | C35: =C33/C34-1 | D35: =D33/D34-1 | E35: =E33/E34-1
A36: Maximum supportable project cost | B36: $ | C36: =C7/(Assumptions!$C$62*Assumptions!$C$58*C9) | D36: =D7/(Assumptions!$D$62*Assumptions!$D$58*D9) | E36: =E7/(Assumptions!$E$62*Assumptions!$E$58*E9) | F36: Approximate - holds NOI constant, so it ignores the small property-tax feedback from a lower cost basis.
A37: Maximum supportable cost per stall | B37: $ / stall | C37: =C36/Assumptions!$C$9 | D37: =D36/Assumptions!$D$9 | E37: =E36/Assumptions!$E$9
A38: vs. modeled all-in cost per stall | B38: $ / stall | C38: =Cost_Per_Stall!$C$46 | D38: =Cost_Per_Stall!$D$46 | E38: =Cost_Per_Stall!$E$46
A39: Maximum supportable land price | B39: $ / acre | C39: =(C36-(C6-Cost_Per_Stall!$C$21))/(Assumptions!$C$6*(1+Assumptions!$C$17)) | D39: =(D36-(D6-Cost_Per_Stall!$D$21))/(Assumptions!$D$6*(1+Assumptions!$D$17)) | E39: =(E36-(E6-Cost_Per_Stall!$E$21))/(Assumptions!$E$6*(1+Assumptions!$E$17)) | F39: Residual land value at a 1.25x DSCR. Compare to the $175k/acre (raw) and $385k/acre (improved) inputs.
A40: Break-even occupancy (1.00x DSCR, max LTC loan) | B40: % of stabilized | C40: =(C22+Revenue_NOI!$C$31)/(1-Revenue_NOI!$C$38)/Revenue_NOI!$C$15 | D40: =(D22+Revenue_NOI!$D$31)/(1-Revenue_NOI!$D$38)/Revenue_NOI!$D$15 | E40: =(E22+Revenue_NOI!$E$31)/(1-Revenue_NOI!$E$38)/Revenue_NOI!$E$15 | F40: Share of stabilized EGI needed just to cover opex and debt service.

Sheet ProForma_10yr
A1: 10-Year Operating Pro Forma - selected scenario
A2: Change the scenario selector in cell C3 (1 = S1, 2 = S2, 3 = S3). Everything below repoints automatically.
A3: SCENARIO SELECTOR -> | C3: 2 | D3: =CHOOSE($C$3,"S1 Greenfield, full-depth asphalt, staffed","S2 Greenfield, value-engineered, unmanned","S3 Retrofit of an existing paved yard")
A5: SELECTED SCENARIO INPUTS
A6: Stalls | B6: stalls | C6: =INDEX(Assumptions!$C$9:$E$9,$C$3)
A7: Stabilized EGI | B7: $ / yr | C7: =INDEX(Revenue_NOI!$C$15:$E$15,$C$3)
A8: Revenue-independent opex | B8: $ / yr | C8: =INDEX(Revenue_NOI!$C$31:$E$31,$C$3)
A9: Revenue-linked opex | B9: % of EGI | C9: =INDEX(Revenue_NOI!$C$38:$E$38,$C$3)
A10: Revenue growth | B10: % p.a. | C10: =INDEX(Assumptions!$C$26:$E$26,$C$3)
A11: Opex growth | B11: % p.a. | C11: =INDEX(Assumptions!$C$44:$E$44,$C$3)
A12: Total project cost | B12: $ | C12: =INDEX(Cost_Per_Stall!$C$38:$E$38,$C$3)
A13: Permanent loan (at max LTC) | B13: $ | C13: =INDEX(Debt_DSCR!$C$10:$E$10,$C$3)
A14: Annual debt constant | B14: % | C14: =INDEX(Debt_DSCR!$C$9:$E$9,$C$3)
A15: Annual debt service | B15: $ / yr | C15: =$C$13*$C$14
A16: Exit cap rate | B16: % | C16: =INDEX(Assumptions!$C$63:$E$63,$C$3)
A17: Equity at close | B17: $ | C17: =$C$12-$C$13
A18: Cost of sale | B18: % of value | C18: 0.02
A20: LEASE-UP RAMP (occupancy as a % of stabilized)
A21: Occupancy ramp - Years 1 / 2 / 3+ | B21: % of stabilized | C21: 0.45 | D21: 0.78 | E21: 1 | F21: Industry guidance: 70% occupancy is a typical stabilization target, reached within ~36 months. Tech-enabled operators report 92-98% once mature.
A23: OPERATING PRO FORMA
A24: Year | C24: 1 | D24: 2 | E24: 3 | F24: 4 | G24: 5 | H24: 6 | I24: 7 | J24: 8 | K24: 9 | L24: 10
A25: Occupancy - % of stabilized | C25: =$C$21 | D25: =$D$21 | E25: =$E$21 | F25: =$E$21 | G25: =$E$21 | H25: =$E$21 | I25: =$E$21 | J25: =$E$21 | K25: =$E$21 | L25: =$E$21
A26: Effective gross income | C26: =$C$7*C25*(1+$C$10)^0 | D26: =$C$7*D25*(1+$C$10)^1 | E26: =$C$7*E25*(1+$C$10)^2 | F26: =$C$7*F25*(1+$C$10)^3 | G26: =$C$7*G25*(1+$C$10)^4 | H26: =$C$7*H25*(1+$C$10)^5 | I26: =$C$7*I25*(1+$C$10)^6 | J26: =$C$7*J25*(1+$C$10)^7 | K26: =$C$7*K25*(1+$C$10)^8 | L26: =$C$7*L25*(1+$C$10)^9
A27: Revenue-independent opex | C27: =-$C$8*(1+$C$11)^0 | D27: =-$C$8*(1+$C$11)^1 | E27: =-$C$8*(1+$C$11)^2 | F27: =-$C$8*(1+$C$11)^3 | G27: =-$C$8*(1+$C$11)^4 | H27: =-$C$8*(1+$C$11)^5 | I27: =-$C$8*(1+$C$11)^6 | J27: =-$C$8*(1+$C$11)^7 | K27: =-$C$8*(1+$C$11)^8 | L27: =-$C$8*(1+$C$11)^9
A28: Revenue-linked opex | C28: =-C26*$C$9 | D28: =-D26*$C$9 | E28: =-E26*$C$9 | F28: =-F26*$C$9 | G28: =-G26*$C$9 | H28: =-H26*$C$9 | I28: =-I26*$C$9 | J28: =-J26*$C$9 | ... L28: =-L26*$C$9
A29: Total operating expenses | C29: =SUM(C27:C28) | D29: =SUM(D27:D28) | E29: =SUM(E27:E28) | F29: =SUM(F27:F28) | G29: =SUM(G27:G28) | H29: =SUM(H27:H28) | I29: =SUM(I27:I28) | J29: =SUM(J27:J28) | ... L29: =SUM(L27:L28)
A30: NET OPERATING INCOME | C30: =C26+C29 | D30: =D26+D29 | E30: =E26+E29 | F30: =F26+F29 | G30: =G26+G29 | H30: =H26+H29 | I30: =I26+I29 | J30: =J26+J29 | ... L30: =L26+L29
A31: Debt service | C31: =-$C$15 | D31: =-$C$15 | E31: =-$C$15 | F31: =-$C$15 | G31: =-$C$15 | H31: =-$C$15 | I31: =-$C$15 | J31: =-$C$15 | ... L31: =-$C$15
A32: Cash flow after debt service | C32: =C30+C31 | D32: =D30+D31 | E32: =E30+E31 | F32: =F30+F31 | G32: =G30+G31 | H32: =H30+H31 | I32: =I30+I31 | J32: =J30+J31 | ... L32: =L30+L31
A33: DSCR | C33: =IF($C$15=0,0,C30/$C$15) | D33: =IF($C$15=0,0,D30/$C$15) | E33: =IF($C$15=0,0,E30/$C$15) | F33: =IF($C$15=0,0,F30/$C$15) | G33: =IF($C$15=0,0,G30/$C$15) | H33: =IF($C$15=0,0,H30/$C$15) | I33: =IF($C$15=0,0,I30/$C$15) | J33: =IF($C$15=0,0,J30/$C$15) | ... L33: =IF($C$15=0,0,L30/$C$15)
A34: Debt yield | C34: =IF($C$13=0,0,C30/$C$13) | D34: =IF($C$13=0,0,D30/$C$13) | E34: =IF($C$13=0,0,E30/$C$13) | F34: =IF($C$13=0,0,F30/$C$13) | G34: =IF($C$13=0,0,G30/$C$13) | H34: =IF($C$13=0,0,H30/$C$13) | I34: =IF($C$13=0,0,I30/$C$13) | J34: =IF($C$13=0,0,J30/$C$13) | ... L34: =IF($C$13=0,0,L30/$C$13)
A35: Yield on cost | C35: =C30/$C$12 | D35: =D30/$C$12 | E35: =E30/$C$12 | F35: =F30/$C$12 | G35: =G30/$C$12 | H35: =H30/$C$12 | I35: =I30/$C$12 | J35: =J30/$C$12 | ... L35: =L30/$C$12
A37: Reversion - Year 10 (value at exit cap, net of sale costs) | L37: =L30*(1+$C$10)/$C$16*(1-$C$18)
A38: Less: loan balance at Year 10 | L38: =-$C$13*(1-(1+INDEX(Assumptions!$C$60:$E$60,$C$3)/12)^-(INDEX(Assumptions!$C$61:$E$61,$C$3)*12-120))/(1-(1+INDEX(Assumptions!$C$60:$E$60,$C$3)/12)^-(INDEX(Assumptions!$C$61:$E$61,$C$3)*12))
A39: Net sale proceeds to equity | L39: =L37+L38
A41: Equity cash flow | B41: =-$C$17 | C41: =C32 | D41: =D32 | E41: =E32 | F41: =F32 | G41: =G32 | H41: =H32 | I41: =I32 | J41: =J32 | K41: =K32 | L41: =L32+L39
A42: Levered equity IRR (10-yr hold) | C42: =IFERROR(IRR(B41:L41),"n/m")
A43: Equity multiple | C43: =IFERROR(SUM(C41:L41)/$C$17+1,"n/m")

Sheet Sensitivity
A1: Sensitivity Analysis - where the deal breaks and what fixes it
A2: Grids are exact re-solves of the same math, not approximations, except where noted. Selector in C3.
A3: SCENARIO SELECTOR -> | C3: 2 | D3: =CHOOSE($C$3,"S1 Greenfield, full-depth asphalt, staffed","S2 Greenfield, value-engineered, unmanned","S3 Retrofit of an existing paved yard")
A5: SELECTED SCENARIO DRIVERS
A6: Stalls | C6: =INDEX(Assumptions!$C$9:$E$9,$C$3)
A7: Revenue-independent opex ($/yr) | C7: =INDEX(Revenue_NOI!$C$31:$E$31,$C$3)
A8: of which real estate taxes | C8: =INDEX(Revenue_NOI!$C$20:$E$20,$C$3)
A9: Revenue-linked opex (% of EGI) | C9: =INDEX(Revenue_NOI!$C$38:$E$38,$C$3)
A10: Annual debt constant | C10: =INDEX(Debt_DSCR!$C$9:$E$9,$C$3)
A11: Target loan to cost | C11: =INDEX(Assumptions!$C$58:$E$58,$C$3)
A12: Minimum DSCR | C12: =INDEX(Assumptions!$C$62:$E$62,$C$3)
A13: Exit cap rate | C13: =INDEX(Assumptions!$C$63:$E$63,$C$3)
A14: Gross acres | C14: =INDEX(Assumptions!$C$6:$E$6,$C$3)
A15: Acquisition closing costs (%) | C15: =INDEX(Assumptions!$C$17:$E$17,$C$3)
A16: Paved SF per stall | C16: =INDEX(Assumptions!$C$8:$E$8,$C$3)
A17: Per-stall discrete items ($/stall) | C17: =INDEX(Capex_Variable!$C$20:$E$20,$C$3)
A18: Variable hard cost ($) | C18: =INDEX(Cost_Per_Stall!$C$7:$E$7,$C$3)
A19: Variable all-in cost ($) | C19: =INDEX(Cost_Per_Stall!$C$41:$E$41,$C$3)
A20: Fixed all-in cost ($) | C20: =INDEX(Cost_Per_Stall!$C$42:$E$42,$C$3)
A21: Land + closing ($) | C21: =INDEX(Cost_Per_Stall!$C$21:$E$21,$C$3)
A22: Land price ($) | C22: =INDEX(Capex_Fixed!$C$6:$E$6,$C$3)
A23: Improvement basis for assessment ($) | C23: =INDEX(Cost_Per_Stall!$C$23:$E$23,$C$3)
A24: CT assessment ratio | C24: =INDEX(Assumptions!$C$29:$E$29,$C$3)
A25: Mill rate | C25: =INDEX(Assumptions!$C$28:$E$28,$C$3)
A26: Assessor factor - land | C26: =INDEX(Assumptions!$C$30:$E$30,$C$3)
A27: All-in cost per stall ($) | C27: =INDEX(Cost_Per_Stall!$C$46:$E$46,$C$3)
A28: Blended revenue per stall / month ($) | C28: =INDEX(Revenue_NOI!$C$16:$E$16,$C$3)
A29: Soft-cost + contingency markup on variable hard | C29: =$C$19/$C$18
A30: Fixed all-in cost excluding land | C30: =$C$20-$C$21
A31: Revenue-independent opex excluding taxes | C31: =$C$7-$C$8
A34: GRID 1 | DSCR at target leverage
A35: DSCR = NOI / debt service, where the loan is the target loan-to-cost applied to the cost-per-stall in the column header. Shaded band below 1.25x is a decline. | C35: All-in cost per stall ->
B36: Blended revenue $ / stall / month | C36: 18000 | D36: 22000 | E36: 26000 | F36: 30000 | G36: 34000 | H36: 38000 | I36: 42000
B37: 250 | C37: =($B37*12*$C$6*(1-$C$9)-$C$7)/($C$11*C$36*$C$6*$C$10) | D37: =($B37*12*$C$6*(1-$C$9)-$C$7)/($C$11*D$36*$C$6*$C$10) | E37: =($B37*12*$C$6*(1-$C$9)-$C$7)/($C$11*E$36*$C$6*$C$10) | F37: =($B37*12*$C$6*(1-$C$9)-$C$7)/($C$11*F$36*$C$6*$C$10) | G37: =($B37*12*$C$6*(1-$C$9)-$C$7)/($C$11*G$36*$C$6*$C$10) | H37: =($B37*12*$C$6*(1-$C$9)-$C$7)/($C$11*H$36*$C$6*$C$10) | I37: =($B37*12*$C$6*(1-$C$9)-$C$7)/($C$11*I$36*$C$6*$C$10)
B38: 275 | C38: =($B38*12*$C$6*(1-$C$9)-$C$7)/($C$11*C$36*$C$6*$C$10) | D38: =($B38*12*$C$6*(1-$C$9)-$C$7)/($C$11*D$36*$C$6*$C$10) | E38: =($B38*12*$C$6*(1-$C$9)-$C$7)/($C$11*E$36*$C$6*$C$10) | F38: =($B38*12*$C$6*(1-$C$9)-$C$7)/($C$11*F$36*$C$6*$C$10) | G38: =($B38*12*$C$6*(1-$C$9)-$C$7)/($C$11*G$36*$C$6*$C$10) | H38: =($B38*12*$C$6*(1-$C$9)-$C$7)/($C$11*H$36*$C$6*$C$10) | I38: =($B38*12*$C$6*(1-$C$9)-$C$7)/($C$11*I$36*$C$6*$C$10)
B39: 300 | C39: =($B39*12*$C$6*(1-$C$9)-$C$7)/($C$11*C$36*$C$6*$C$10) | D39: =($B39*12*$C$6*(1-$C$9)-$C$7)/($C$11*D$36*$C$6*$C$10) | E39: =($B39*12*$C$6*(1-$C$9)-$C$7)/($C$11*E$36*$C$6*$C$10) | F39: =($B39*12*$C$6*(1-$C$9)-$C$7)/($C$11*F$36*$C$6*$C$10) | G39: =($B39*12*$C$6*(1-$C$9)-$C$7)/($C$11*G$36*$C$6*$C$10) | H39: =($B39*12*$C$6*(1-$C$9)-$C$7)/($C$11*H$36*$C$6*$C$10) | I39: =($B39*12*$C$6*(1-$C$9)-$C$7)/($C$11*I$36*$C$6*$C$10)
B40: 325 | C40: =($B40*12*$C$6*(1-$C$9)-$C$7)/($C$11*C$36*$C$6*$C$10) | D40: =($B40*12*$C$6*(1-$C$9)-$C$7)/($C$11*D$36*$C$6*$C$10) | E40: =($B40*12*$C$6*(1-$C$9)-$C$7)/($C$11*E$36*$C$6*$C$10) | F40: =($B40*12*$C$6*(1-$C$9)-$C$7)/($C$11*F$36*$C$6*$C$10) | G40: =($B40*12*$C$6*(1-$C$9)-$C$7)/($C$11*G$36*$C$6*$C$10) | H40: =($B40*12*$C$6*(1-$C$9)-$C$7)/($C$11*H$36*$C$6*$C$10) | I40: =($B40*12*$C$6*(1-$C$9)-$C$7)/($C$11*I$36*$C$6*$C$10)
B41: 350 | C41: =($B41*12*$C$6*(1-$C$9)-$C$7)/($C$11*C$36*$C$6*$C$10) | D41: =($B41*12*$C$6*(1-$C$9)-$C$7)/($C$11*D$36*$C$6*$C$10) | E41: =($B41*12*$C$6*(1-$C$9)-$C$7)/($C$11*E$36*$C$6*$C$10) | F41: =($B41*12*$C$6*(1-$C$9)-$C$7)/($C$11*F$36*$C$6*$C$10) | G41: =($B41*12*$C$6*(1-$C$9)-$C$7)/($C$11*G$36*$C$6*$C$10) | H41: =($B41*12*$C$6*(1-$C$9)-$C$7)/($C$11*H$36*$C$6*$C$10) | I41: =($B41*12*$C$6*(1-$C$9)-$C$7)/($C$11*I$36*$C$6*$C$10)
B42: 375 | C42: =($B42*12*$C$6*(1-$C$9)-$C$7)/($C$11*C$36*$C$6*$C$10) | D42: =($B42*12*$C$6*(1-$C$9)-$C$7)/($C$11*D$36*$C$6*$C$10) | E42: =($B42*12*$C$6*(1-$C$9)-$C$7)/($C$11*E$36*$C$6*$C$10) | F42: =($B42*12*$C$6*(1-$C$9)-$C$7)/($C$11*F$36*$C$6*$C$10) | G42: =($B42*12*$C$6*(1-$C$9)-$C$7)/($C$11*G$36*$C$6*$C$10) | H42: =($B42*12*$C$6*(1-$C$9)-$C$7)/($C$11*H$36*$C$6*$C$10) | I42: =($B42*12*$C$6*(1-$C$9)-$C$7)/($C$11*I$36*$C$6*$C$10)
B43: 400 | C43: =($B43*12*$C$6*(1-$C$9)-$C$7)/($C$11*C$36*$C$6*$C$10) | D43: =($B43*12*$C$6*(1-$C$9)-$C$7)/($C$11*D$36*$C$6*$C$10) | E43: =($B43*12*$C$6*(1-$C$9)-$C$7)/($C$11*E$36*$C$6*$C$10) | F43: =($B43*12*$C$6*(1-$C$9)-$C$7)/($C$11*F$36*$C$6*$C$10) | G43: =($B43*12*$C$6*(1-$C$9)-$C$7)/($C$11*G$36*$C$6*$C$10) | H43: =($B43*12*$C$6*(1-$C$9)-$C$7)/($C$11*H$36*$C$6*$C$10) | I43: =($B43*12*$C$6*(1-$C$9)-$C$7)/($C$11*I$36*$C$6*$C$10)
...

Sheet Sources_Notes
A1: Sources, Benchmarks & Modeling Notes
A2: Every hardcoded number in this model traces to one of the benchmarks below, to a stated engineering calculation, or to a labeled judgment call.
A4: Topic | B4: What it establishes | C4: Source
A5: CT truck parking demand | B5: CT has roughly 1,238 truck parking spaces; 92% of demand concentrates on I-95, I-84, I-91 and I-395, mostly overnight; demand projected to grow 18% by 2040. Establishes that the shortage is real and structural. | C5: CTDOT statewide truck parking study / CT Freight Plan - portal.ct.gov/dot
A6: Public supply expansion | B6: $31M CTDOT program adds 180+ spaces at Middletown, Madison, Southington, Southbury and Vernon by ~2030, taking public capacity from ~420 to ~600. Implies ~$172k per space at public prevailing-wage pricing, and is the competitive backdrop for any private facility. | C6: CTDOT press release (2024); Hartford Business Journal; CCJ
A7: Development cost - rule of thumb | B7: $100k-$200k per acre for new truck parking construction excluding land; standard yield 25 trucks/acre; implies $4,000-$8,000 per stall. Used as a low-cost-market floor, NOT as the Connecticut number. | C7: Truck Parking Club - Cost of Building a Truck Parking Lot
A8: Surface parking cost - national | B8: $4,500-$6,800 per completed surface space in 2026 including paving, drainage, striping, lighting, signage and basic technology. | C8: Wins Parking - Parking Lot Construction Cost Guide (2026)
A9: Paving cost - heavy duty | B9: Commercial asphalt $4-$10/SF; heavy-duty truck sections $7-$12+/SF (4-6" asphalt over 10-12"+ aggregate base). CT specifically $4-$11/SF, with CT construction costs ~1.32x the national average. | C9: Asphalt Coatings Co.; The Pavement Group; CostFlowAI CT calculator
A10: Stall geometry | B10: A tractor-trailer stall is ~14' x 75'; a trailer-only stall ~14' x 55'. Model uses 12' x 75' plus half of a 75' back-in aisle = 1,450 SF per stall all-in. | C10: Truck Parking Club; standard AASHTO/industry layout practice
A11: Parking rates - national bands | B11: $12-$25 per night at chain travel centers; $50-$150/month for bobtails and box trucks at private lots; $150-$500+/month for full tractor-trailer configurations, regionally dependent. | C11: RecNation - How Much Is Truck Parking
A12: Parking rates - Hartford metro | B12: Hartford ~$81/month average for 22' tractor spaces; East Hartford ~$96; West Hartford ~$106 (12-35' spaces). These are small-vehicle spaces, so they set a FLOOR, not the 53' secured rate. Model uses $315-$340/month for a secured, lit, gated 53' stall. | C12: Neighbor.com marketplace listings, Hartford / East Hartford / West Hartford
A13: Occupancy & stabilization | B13: 70% occupancy is a typical stabilization target, generally reached within ~36 months; professionally managed, tech-enabled facilities report 92-98%. Model underwrites 88-90% stabilized with a 45% / 78% / 100% ramp. | C13: Truck Parking Club development materials; Truckspace
A14: IOS cap rates | B14: 2026: 6.00-6.75% for stabilized institutional IOS in primary markets; 6.75-7.75% in secondary markets; broader range 6.5-9.0%. IOS prices 25-75 bps wide of comparable industrial. Hartford is secondary. | C14: Matthews 2026 IOS Sector Update; Commercial Lending Solutions
A15: Debt terms | B15: Commercial mortgage rates start ~5.74% (Aug 2026); industrial bridge 7.5-9.5%; DSCR floors 1.25x for core, 1.30-1.40x for other property types; 25-year amortization available. | C15: Select Commercial; PeerSense; Commercial Lending USA
... A20: Insurance | B20: IOS truck-parking operators need garagekeepers legal liability in addition to standard GL and property - a coverage line that does not appear in a generic parking-lot pro forma. | C20: CNS Insurance; InsuranceHub - insurance for truck parking lots
A22: MODELING NOTES & KNOWN LIMITATIONS
A23: - Stall count is derived, not asserted: gross acres x 43,560 x net yard efficiency / 1,450 SF per stall. Change any of the three and the whole model repoints.
A24: - Fixed vs. variable split: variable = yard construction ($/SF of paved area) plus per-stall discrete items (lighting, electrical, pedestals, camera density). Everything else - land, entitlement, stormwater basin, gatehouse, fence, gates, security head-end, utilities, financing, lease-up reserve - is fixed. Soft-cost loadings and contingency are allocated pro-rata by share of hard cost.
A25: - Property taxes are modeled on an assessor factor applied to cost basis, not on an income-approach valuation. A CT assessor may use either. Grid 4 on the Sensitivity tab shows the full range of outcomes; this is the single largest soft spot in the model.
A26: - There is no circular reference: the lease-up reserve depends on stabilized opex, and opex depends on the capitalized cost BEFORE the reserve. Do not repoint the tax formula at total project cost or the workbook will become circular.
A27: - Break-even solves hold NOI constant, so the maximum supportable cost and maximum land price ignore the second-order property-tax relief from a lower cost basis. Both are therefore mildly conservative.
A28: - No revenue is assumed from a truck wash, fuel, a repair bay or a convenience store. Those are separate businesses with their own capex and are the usual way a highway-adjacent truck stop closes an economics gap - Bloomfield's off-highway location makes them harder to justify.
A29: - Environmental risk is carried as an allowance, not a budget. CT's Release-Based Remediation program replaced the Transfer Act; a previously-industrial paved yard (S3) can carry remediation exposure well beyond the $95,000 allowance shown.
A30: - Ledge and unsuitable soils are the largest single greenfield cost shock in this part of Connecticut and are covered only by the general contingency. A geotechnical investigation should precede any hard commitment on land.

Sheet Scale_Density
A1: Scale & Density - the dominant lever on cost per stall
A2: Fixed site costs are 56-81% of this deal's capital cost, so cost per stall falls fast with site size and stall density. Selector in C3.
A3: SCENARIO SELECTOR -> | C3: 2 | D3: =CHOOSE($C$3,"S1 Greenfield, full-depth asphalt, staffed","S2 Greenfield, value-engineered, unmanned","S3 Retrofit of an existing paved yard")
A5: SELECTED SCENARIO DRIVERS
A6: Base gross acres | C6: =INDEX(Assumptions!$C$6:$E$6,$C$3)
A7: Net yard efficiency | C7: =INDEX(Assumptions!$C$7:$E$7,$C$3)
A8: Land price ($/acre) | C8: =INDEX(Assumptions!$C$15:$E$15,$C$3)
A9: Acquisition closing costs | C9: =INDEX(Assumptions!$C$17:$E$17,$C$3)
A10: Yard construction ($/SF) | C10: =INDEX(Capex_Variable!$C$12:$E$12,$C$3)
A11: Per-stall discrete items ($/stall) | C11: =INDEX(Capex_Variable!$C$20:$E$20,$C$3)
A12: Base variable hard cost ($) | C12: =INDEX(Cost_Per_Stall!$C$7:$E$7,$C$3)
A13: Base variable all-in cost ($) | C13: =INDEX(Cost_Per_Stall!$C$41:$E$41,$C$3)
A14: Base fixed all-in cost ($) | C14: =INDEX(Cost_Per_Stall!$C$42:$E$42,$C$3)
A15: Base land + closing ($) | C15: =INDEX(Cost_Per_Stall!$C$21:$E$21,$C$3)
A16: Insurance ($/stall/yr) | C16: =INDEX(Assumptions!$C$32:$E$32,$C$3)
A17: Repairs & maintenance ($/stall/yr) | C17: =INDEX(Assumptions!$C$36:$E$36,$C$3)
A18: Utilities ($/stall/yr) | C18: =INDEX(Assumptions!$C$37:$E$37,$C$3)
A19: Trash & restrooms ($/stall/yr) | C19: =INDEX(Assumptions!$C$38:$E$38,$C$3)
A20: Marketing ($/stall/yr) | C20: =INDEX(Assumptions!$C$41:$E$41,$C$3)
A21: Replacement reserve ($/stall/yr) | C21: =INDEX(Assumptions!$C$43:$E$43,$C$3)
A22: Snow & ice ($/paved acre/yr) | C22: =INDEX(Assumptions!$C$35:$E$35,$C$3)
A23: On-site staffing ($/yr) | C23: =INDEX(Assumptions!$C$33:$E$33,$C$3)
A24: Remote monitoring ($/yr) | C24: =INDEX(Assumptions!$C$34:$E$34,$C$3)
A25: Professional fees ($/yr) | C25: =INDEX(Assumptions!$C$42:$E$42,$C$3)
A26: Revenue-linked opex (% of EGI) | C26: =INDEX(Revenue_NOI!$C$38:$E$38,$C$3)
A27: CT assessment ratio | C27: =INDEX(Assumptions!$C$29:$E$29,$C$3)
A28: Mill rate | C28: =INDEX(Assumptions!$C$28:$E$28,$C$3)
A29: Assessor factor - improvements | C29: =INDEX(Assumptions!$C$31:$E$31,$C$3)
A30: Target loan to cost | C30: =INDEX(Assumptions!$C$58:$E$58,$C$3)
A31: Annual debt constant | C31: =INDEX(Debt_DSCR!$C$9:$E$9,$C$3)
A32: Soft + contingency markup on variable hard | C32: =$C$13/$C$12
A33: Base fixed all-in cost excluding land | C33: =$C$14-$C$15
A34: Share of non-land fixed cost that scales with site area | C34: 0.4 | E34: Stormwater, perimeter fence, entry work and mass E&S scale with acreage; entitlement, gatehouse, gates, security head-end and design do not.
A35: Fixed cost - flat component ($) | C35: =$C$33*(1-$C$34)
A36: Fixed cost - per gross acre ($) | C36: =$C$33*$C$34/$C$6
A37: Blended revenue per stall per month | C37: =INDEX(Revenue_NOI!$C$16:$E$16,$C$3) | E37: Overwrite with a hardcoded rate to test a different pricing assumption across the whole grid.
A38: Per-stall opex ($/stall/yr) | C38: =$C$16+$C$17+$C$18+$C$19+$C$20+$C$21
A39: Flat opex ($/yr) | C39: =$C$23+$C$24+$C$25
A40: Snow & ice ($/paved SF/yr) | C40: =$C$22/43560
A42: GRID A | Stall count
...
